2023-06-19 15:03:17,858 - SuPy - INFO - All cache cleared.
2023-06-19 15:03:17,876 - SuPy - ERROR - C:\Users\xbacos\OneDrive - University of Gothenburg\Artikel_4\temp\w\RunControl.nml does not exists!
Traceback (most recent call last):
  File "C:\OSGeo4W\apps\Python39\lib\site-packages\supy\_load.py", line 232, in load_SUEWS_nml_simple
    df_res = pd.DataFrame(f90nml.read(str_file))
  File "C:\Users\xbacos\AppData\Roaming\Python\Python39\site-packages\f90nml\__init__.py", line 31, in read
    return parser.read(nml_path)
  File "C:\Users\xbacos\AppData\Roaming\Python\Python39\site-packages\f90nml\parser.py", line 279, in read
    nml_file = open(nml_fname, 'r') if nml_is_path else nml_fname
FileNotFoundError: [Errno 2] No such file or directory: 'C:\\Users\\xbacos\\OneDrive - University of Gothenburg\\Artikel_4\\temp\\w\\RunControl.nml'
2023-06-19 15:05:02,736 - SuPy - INFO - All cache cleared.
2023-06-19 15:05:02,935 - SuPy - ERROR - error [Errno 2] No such file or directory: 'C:\\Users\\xbacos\\OneDrive - University of Gothenburg\\Artikel_4\\temp\\w\\SUEWS_WithinGridWaterDist.txt' in reading C:\Users\xbacos\OneDrive - University of Gothenburg\Artikel_4\temp\w\SUEWS_WithinGridWaterDist.txt!
Traceback (most recent call last):
  File "C:\OSGeo4W\apps\Python39\lib\site-packages\supy\_load.py", line 271, in load_SUEWS_table
    rawdata = pd.read_csv(
  File "C:\Users\xbacos\AppData\Roaming\Python\Python39\site-packages\pandas\util\_decorators.py", line 311, in wrapper
    return func(*args, **kwargs)
  File "C:\Users\xbacos\AppData\Roaming\Python\Python39\site-packages\pandas\io\parsers\readers.py", line 680, in read_csv
    return _read(filepath_or_buffer, kwds)
  File "C:\Users\xbacos\AppData\Roaming\Python\Python39\site-packages\pandas\io\parsers\readers.py", line 575, in _read
    parser = TextFileReader(filepath_or_buffer, **kwds)
  File "C:\Users\xbacos\AppData\Roaming\Python\Python39\site-packages\pandas\io\parsers\readers.py", line 934, in __init__
    self._engine = self._make_engine(f, self.engine)
  File "C:\Users\xbacos\AppData\Roaming\Python\Python39\site-packages\pandas\io\parsers\readers.py", line 1218, in _make_engine
    self.handles = get_handle(  # type: ignore[call-overload]
  File "C:\Users\xbacos\AppData\Roaming\Python\Python39\site-packages\pandas\io\common.py", line 786, in get_handle
    handle = open(
FileNotFoundError: [Errno 2] No such file or directory: 'C:\\Users\\xbacos\\OneDrive - University of Gothenburg\\Artikel_4\\temp\\w\\SUEWS_WithinGridWaterDist.txt'
2023-06-19 15:05:18,340 - SuPy - INFO - All cache cleared.
2023-06-19 15:19:59,398 - SuPy - INFO - All cache cleared.
2023-06-19 15:21:38,092 - SuPy - INFO - All cache cleared.
2023-06-19 15:22:47,601 - SuPy - INFO - All cache cleared.
2023-06-19 15:24:06,371 - SuPy - INFO - All cache cleared.
2023-06-19 15:24:32,190 - SuPy - INFO - All cache cleared.
2023-06-19 15:24:46,057 - SuPy - INFO - All cache cleared.
2023-06-19 15:24:46,071 - SuPy - ERROR - error [Errno 2] No such file or directory: 'C:\\Users\\xbacos\\OneDrive - University of Gothenburg\\Artikel_4\\temp\\w\\SUEWS_AnthropogenicEmission.txt' in reading C:\Users\xbacos\OneDrive - University of Gothenburg\Artikel_4\temp\w\SUEWS_AnthropogenicEmission.txt!
Traceback (most recent call last):
  File "C:\OSGeo4W\apps\Python39\lib\site-packages\supy\_load.py", line 271, in load_SUEWS_table
    rawdata = pd.read_csv(
  File "C:\Users\xbacos\AppData\Roaming\Python\Python39\site-packages\pandas\util\_decorators.py", line 311, in wrapper
    return func(*args, **kwargs)
  File "C:\Users\xbacos\AppData\Roaming\Python\Python39\site-packages\pandas\io\parsers\readers.py", line 680, in read_csv
    return _read(filepath_or_buffer, kwds)
  File "C:\Users\xbacos\AppData\Roaming\Python\Python39\site-packages\pandas\io\parsers\readers.py", line 575, in _read
    parser = TextFileReader(filepath_or_buffer, **kwds)
  File "C:\Users\xbacos\AppData\Roaming\Python\Python39\site-packages\pandas\io\parsers\readers.py", line 934, in __init__
    self._engine = self._make_engine(f, self.engine)
  File "C:\Users\xbacos\AppData\Roaming\Python\Python39\site-packages\pandas\io\parsers\readers.py", line 1218, in _make_engine
    self.handles = get_handle(  # type: ignore[call-overload]
  File "C:\Users\xbacos\AppData\Roaming\Python\Python39\site-packages\pandas\io\common.py", line 786, in get_handle
    handle = open(
FileNotFoundError: [Errno 2] No such file or directory: 'C:\\Users\\xbacos\\OneDrive - University of Gothenburg\\Artikel_4\\temp\\w\\SUEWS_AnthropogenicEmission.txt'
2023-06-19 15:25:46,712 - SuPy - INFO - All cache cleared.
2023-06-19 15:25:46,716 - SuPy - ERROR - C:\Users\xbacos\OneDrive - University of Gothenburg\Artikel_4\temp\input\old_suewsprep\RunControl.nml does not exists!
Traceback (most recent call last):
  File "C:\OSGeo4W\apps\Python39\lib\site-packages\supy\_load.py", line 232, in load_SUEWS_nml_simple
    df_res = pd.DataFrame(f90nml.read(str_file))
  File "C:\Users\xbacos\AppData\Roaming\Python\Python39\site-packages\f90nml\__init__.py", line 31, in read
    return parser.read(nml_path)
  File "C:\Users\xbacos\AppData\Roaming\Python\Python39\site-packages\f90nml\parser.py", line 279, in read
    nml_file = open(nml_fname, 'r') if nml_is_path else nml_fname
FileNotFoundError: [Errno 2] No such file or directory: 'C:\\Users\\xbacos\\OneDrive - University of Gothenburg\\Artikel_4\\temp\\input\\old_suewsprep\\RunControl.nml'
2023-06-19 15:26:20,387 - SuPy - INFO - All cache cleared.
2023-06-19 15:34:04,403 - SuPy - INFO - All cache cleared.
2023-06-19 15:35:44,795 - SuPy - INFO - All cache cleared.
2023-06-19 15:36:43,094 - SuPy - INFO - All cache cleared.
2023-06-19 15:44:48,958 - SuPy - INFO - All cache cleared.
2023-06-19 15:44:49,091 - SuPy - ERROR - Entries missing from SUEWS_AnthropogenicEmission.txt
Traceback (most recent call last):
  File "C:\OSGeo4W\apps\Python39\lib\site-packages\supy\_load.py", line 887, in build_code_df
    df_code = df_code0.loc[list_code, list_keys]
  File "C:\Users\xbacos\AppData\Roaming\Python\Python39\site-packages\pandas\core\indexing.py", line 961, in __getitem__
    return self._getitem_tuple(key)
  File "C:\Users\xbacos\AppData\Roaming\Python\Python39\site-packages\pandas\core\indexing.py", line 1140, in _getitem_tuple
    return self._getitem_lowerdim(tup)
  File "C:\Users\xbacos\AppData\Roaming\Python\Python39\site-packages\pandas\core\indexing.py", line 843, in _getitem_lowerdim
    return self._getitem_nested_tuple(tup)
  File "C:\Users\xbacos\AppData\Roaming\Python\Python39\site-packages\pandas\core\indexing.py", line 942, in _getitem_nested_tuple
    obj = getattr(obj, self.name)._getitem_axis(key, axis=axis)
  File "C:\Users\xbacos\AppData\Roaming\Python\Python39\site-packages\pandas\core\indexing.py", line 1191, in _getitem_axis
    return self._getitem_iterable(key, axis=axis)
  File "C:\Users\xbacos\AppData\Roaming\Python\Python39\site-packages\pandas\core\indexing.py", line 1132, in _getitem_iterable
    keyarr, indexer = self._get_listlike_indexer(key, axis)
  File "C:\Users\xbacos\AppData\Roaming\Python\Python39\site-packages\pandas\core\indexing.py", line 1327, in _get_listlike_indexer
    keyarr, indexer = ax._get_indexer_strict(key, axis_name)
  File "C:\Users\xbacos\AppData\Roaming\Python\Python39\site-packages\pandas\core\indexes\base.py", line 5782, in _get_indexer_strict
    self._raise_if_missing(keyarr, indexer, axis_name)
  File "C:\Users\xbacos\AppData\Roaming\Python\Python39\site-packages\pandas\core\indexes\base.py", line 5842, in _raise_if_missing
    raise KeyError(f"None of [{key}] are in the [{axis_name}]")
KeyError: "None of [Int64Index([64, 64, 64, 64, 64, 64, 64, 64, 64, 64, 64, 64, 64, 64, 64, 64, 64,\n            64, 64, 64, 64, 64, 64, 64, 64, 64, 64, 64, 64, 64],\n           dtype='int64', name='Code')] are in the [index]"
2023-06-19 15:44:49,094 - SuPy - ERROR - missing code:
 [64, 64, 64, 64, 64, 64, 64, 64, 64, 64, 64, 64, 64, 64, 64, 64, 64, 64, 64, 64, 64, 64, 64, 64, 64, 64, 64, 64, 64, 64]
Traceback (most recent call last):
  File "C:\OSGeo4W\apps\Python39\lib\site-packages\supy\_load.py", line 887, in build_code_df
    df_code = df_code0.loc[list_code, list_keys]
  File "C:\Users\xbacos\AppData\Roaming\Python\Python39\site-packages\pandas\core\indexing.py", line 961, in __getitem__
    return self._getitem_tuple(key)
  File "C:\Users\xbacos\AppData\Roaming\Python\Python39\site-packages\pandas\core\indexing.py", line 1140, in _getitem_tuple
    return self._getitem_lowerdim(tup)
  File "C:\Users\xbacos\AppData\Roaming\Python\Python39\site-packages\pandas\core\indexing.py", line 843, in _getitem_lowerdim
    return self._getitem_nested_tuple(tup)
  File "C:\Users\xbacos\AppData\Roaming\Python\Python39\site-packages\pandas\core\indexing.py", line 942, in _getitem_nested_tuple
    obj = getattr(obj, self.name)._getitem_axis(key, axis=axis)
  File "C:\Users\xbacos\AppData\Roaming\Python\Python39\site-packages\pandas\core\indexing.py", line 1191, in _getitem_axis
    return self._getitem_iterable(key, axis=axis)
  File "C:\Users\xbacos\AppData\Roaming\Python\Python39\site-packages\pandas\core\indexing.py", line 1132, in _getitem_iterable
    keyarr, indexer = self._get_listlike_indexer(key, axis)
  File "C:\Users\xbacos\AppData\Roaming\Python\Python39\site-packages\pandas\core\indexing.py", line 1327, in _get_listlike_indexer
    keyarr, indexer = ax._get_indexer_strict(key, axis_name)
  File "C:\Users\xbacos\AppData\Roaming\Python\Python39\site-packages\pandas\core\indexes\base.py", line 5782, in _get_indexer_strict
    self._raise_if_missing(keyarr, indexer, axis_name)
  File "C:\Users\xbacos\AppData\Roaming\Python\Python39\site-packages\pandas\core\indexes\base.py", line 5842, in _raise_if_missing
    raise KeyError(f"None of [{key}] are in the [{axis_name}]")
KeyError: "None of [Int64Index([64, 64, 64, 64, 64, 64, 64, 64, 64, 64, 64, 64, 64, 64, 64, 64, 64,\n            64, 64, 64, 64, 64, 64, 64, 64, 64, 64, 64, 64, 64],\n           dtype='int64', name='Code')] are in the [index]"
2023-06-19 15:44:49,097 - SuPy - ERROR - `df_code0` has been dumped into C:\GitHub\suews_prepare_database\df_code0.pkl for debugging!
Traceback (most recent call last):
  File "C:\OSGeo4W\apps\Python39\lib\site-packages\supy\_load.py", line 887, in build_code_df
    df_code = df_code0.loc[list_code, list_keys]
  File "C:\Users\xbacos\AppData\Roaming\Python\Python39\site-packages\pandas\core\indexing.py", line 961, in __getitem__
    return self._getitem_tuple(key)
  File "C:\Users\xbacos\AppData\Roaming\Python\Python39\site-packages\pandas\core\indexing.py", line 1140, in _getitem_tuple
    return self._getitem_lowerdim(tup)
  File "C:\Users\xbacos\AppData\Roaming\Python\Python39\site-packages\pandas\core\indexing.py", line 843, in _getitem_lowerdim
    return self._getitem_nested_tuple(tup)
  File "C:\Users\xbacos\AppData\Roaming\Python\Python39\site-packages\pandas\core\indexing.py", line 942, in _getitem_nested_tuple
    obj = getattr(obj, self.name)._getitem_axis(key, axis=axis)
  File "C:\Users\xbacos\AppData\Roaming\Python\Python39\site-packages\pandas\core\indexing.py", line 1191, in _getitem_axis
    return self._getitem_iterable(key, axis=axis)
  File "C:\Users\xbacos\AppData\Roaming\Python\Python39\site-packages\pandas\core\indexing.py", line 1132, in _getitem_iterable
    keyarr, indexer = self._get_listlike_indexer(key, axis)
  File "C:\Users\xbacos\AppData\Roaming\Python\Python39\site-packages\pandas\core\indexing.py", line 1327, in _get_listlike_indexer
    keyarr, indexer = ax._get_indexer_strict(key, axis_name)
  File "C:\Users\xbacos\AppData\Roaming\Python\Python39\site-packages\pandas\core\indexes\base.py", line 5782, in _get_indexer_strict
    self._raise_if_missing(keyarr, indexer, axis_name)
  File "C:\Users\xbacos\AppData\Roaming\Python\Python39\site-packages\pandas\core\indexes\base.py", line 5842, in _raise_if_missing
    raise KeyError(f"None of [{key}] are in the [{axis_name}]")
KeyError: "None of [Int64Index([64, 64, 64, 64, 64, 64, 64, 64, 64, 64, 64, 64, 64, 64, 64, 64, 64,\n            64, 64, 64, 64, 64, 64, 64, 64, 64, 64, 64, 64, 64],\n           dtype='int64', name='Code')] are in the [index]"
2023-06-19 15:45:12,742 - SuPy - INFO - All cache cleared.
2023-06-19 15:45:12,972 - SuPy - ERROR - Entries missing from SUEWS_BiogenCO2.txt
Traceback (most recent call last):
  File "C:\OSGeo4W\apps\Python39\lib\site-packages\supy\_load.py", line 887, in build_code_df
    df_code = df_code0.loc[list_code, list_keys]
  File "C:\Users\xbacos\AppData\Roaming\Python\Python39\site-packages\pandas\core\indexing.py", line 961, in __getitem__
    return self._getitem_tuple(key)
  File "C:\Users\xbacos\AppData\Roaming\Python\Python39\site-packages\pandas\core\indexing.py", line 1140, in _getitem_tuple
    return self._getitem_lowerdim(tup)
  File "C:\Users\xbacos\AppData\Roaming\Python\Python39\site-packages\pandas\core\indexing.py", line 843, in _getitem_lowerdim
    return self._getitem_nested_tuple(tup)
  File "C:\Users\xbacos\AppData\Roaming\Python\Python39\site-packages\pandas\core\indexing.py", line 942, in _getitem_nested_tuple
    obj = getattr(obj, self.name)._getitem_axis(key, axis=axis)
  File "C:\Users\xbacos\AppData\Roaming\Python\Python39\site-packages\pandas\core\indexing.py", line 1191, in _getitem_axis
    return self._getitem_iterable(key, axis=axis)
  File "C:\Users\xbacos\AppData\Roaming\Python\Python39\site-packages\pandas\core\indexing.py", line 1132, in _getitem_iterable
    keyarr, indexer = self._get_listlike_indexer(key, axis)
  File "C:\Users\xbacos\AppData\Roaming\Python\Python39\site-packages\pandas\core\indexing.py", line 1327, in _get_listlike_indexer
    keyarr, indexer = ax._get_indexer_strict(key, axis_name)
  File "C:\Users\xbacos\AppData\Roaming\Python\Python39\site-packages\pandas\core\indexes\base.py", line 5782, in _get_indexer_strict
    self._raise_if_missing(keyarr, indexer, axis_name)
  File "C:\Users\xbacos\AppData\Roaming\Python\Python39\site-packages\pandas\core\indexes\base.py", line 5842, in _raise_if_missing
    raise KeyError(f"None of [{key}] are in the [{axis_name}]")
KeyError: "None of [Int64Index([-2147483648, -2147483648, -2147483648, -2147483648, -2147483648,\n            -2147483648, -2147483648, -2147483648, -2147483648, -2147483648,\n            -2147483648, -2147483648, -2147483648, -2147483648, -2147483648,\n            -2147483648, -2147483648, -2147483648, -2147483648, -2147483648,\n            -2147483648, -2147483648, -2147483648, -2147483648, -2147483648,\n            -2147483648, -2147483648, -2147483648, -2147483648, -2147483648],\n           dtype='int64', name='Code')] are in the [index]"
2023-06-19 15:45:12,974 - SuPy - ERROR - missing code:
 [-2147483648, -2147483648, -2147483648, -2147483648, -2147483648, -2147483648, -2147483648, -2147483648, -2147483648, -2147483648, -2147483648, -2147483648, -2147483648, -2147483648, -2147483648, -2147483648, -2147483648, -2147483648, -2147483648, -2147483648, -2147483648, -2147483648, -2147483648, -2147483648, -2147483648, -2147483648, -2147483648, -2147483648, -2147483648, -2147483648]
Traceback (most recent call last):
  File "C:\OSGeo4W\apps\Python39\lib\site-packages\supy\_load.py", line 887, in build_code_df
    df_code = df_code0.loc[list_code, list_keys]
  File "C:\Users\xbacos\AppData\Roaming\Python\Python39\site-packages\pandas\core\indexing.py", line 961, in __getitem__
    return self._getitem_tuple(key)
  File "C:\Users\xbacos\AppData\Roaming\Python\Python39\site-packages\pandas\core\indexing.py", line 1140, in _getitem_tuple
    return self._getitem_lowerdim(tup)
  File "C:\Users\xbacos\AppData\Roaming\Python\Python39\site-packages\pandas\core\indexing.py", line 843, in _getitem_lowerdim
    return self._getitem_nested_tuple(tup)
  File "C:\Users\xbacos\AppData\Roaming\Python\Python39\site-packages\pandas\core\indexing.py", line 942, in _getitem_nested_tuple
    obj = getattr(obj, self.name)._getitem_axis(key, axis=axis)
  File "C:\Users\xbacos\AppData\Roaming\Python\Python39\site-packages\pandas\core\indexing.py", line 1191, in _getitem_axis
    return self._getitem_iterable(key, axis=axis)
  File "C:\Users\xbacos\AppData\Roaming\Python\Python39\site-packages\pandas\core\indexing.py", line 1132, in _getitem_iterable
    keyarr, indexer = self._get_listlike_indexer(key, axis)
  File "C:\Users\xbacos\AppData\Roaming\Python\Python39\site-packages\pandas\core\indexing.py", line 1327, in _get_listlike_indexer
    keyarr, indexer = ax._get_indexer_strict(key, axis_name)
  File "C:\Users\xbacos\AppData\Roaming\Python\Python39\site-packages\pandas\core\indexes\base.py", line 5782, in _get_indexer_strict
    self._raise_if_missing(keyarr, indexer, axis_name)
  File "C:\Users\xbacos\AppData\Roaming\Python\Python39\site-packages\pandas\core\indexes\base.py", line 5842, in _raise_if_missing
    raise KeyError(f"None of [{key}] are in the [{axis_name}]")
KeyError: "None of [Int64Index([-2147483648, -2147483648, -2147483648, -2147483648, -2147483648,\n            -2147483648, -2147483648, -2147483648, -2147483648, -2147483648,\n            -2147483648, -2147483648, -2147483648, -2147483648, -2147483648,\n            -2147483648, -2147483648, -2147483648, -2147483648, -2147483648,\n            -2147483648, -2147483648, -2147483648, -2147483648, -2147483648,\n            -2147483648, -2147483648, -2147483648, -2147483648, -2147483648],\n           dtype='int64', name='Code')] are in the [index]"
2023-06-19 15:45:12,975 - SuPy - ERROR - `df_code0` has been dumped into C:\GitHub\suews_prepare_database\df_code0.pkl for debugging!
Traceback (most recent call last):
  File "C:\OSGeo4W\apps\Python39\lib\site-packages\supy\_load.py", line 887, in build_code_df
    df_code = df_code0.loc[list_code, list_keys]
  File "C:\Users\xbacos\AppData\Roaming\Python\Python39\site-packages\pandas\core\indexing.py", line 961, in __getitem__
    return self._getitem_tuple(key)
  File "C:\Users\xbacos\AppData\Roaming\Python\Python39\site-packages\pandas\core\indexing.py", line 1140, in _getitem_tuple
    return self._getitem_lowerdim(tup)
  File "C:\Users\xbacos\AppData\Roaming\Python\Python39\site-packages\pandas\core\indexing.py", line 843, in _getitem_lowerdim
    return self._getitem_nested_tuple(tup)
  File "C:\Users\xbacos\AppData\Roaming\Python\Python39\site-packages\pandas\core\indexing.py", line 942, in _getitem_nested_tuple
    obj = getattr(obj, self.name)._getitem_axis(key, axis=axis)
  File "C:\Users\xbacos\AppData\Roaming\Python\Python39\site-packages\pandas\core\indexing.py", line 1191, in _getitem_axis
    return self._getitem_iterable(key, axis=axis)
  File "C:\Users\xbacos\AppData\Roaming\Python\Python39\site-packages\pandas\core\indexing.py", line 1132, in _getitem_iterable
    keyarr, indexer = self._get_listlike_indexer(key, axis)
  File "C:\Users\xbacos\AppData\Roaming\Python\Python39\site-packages\pandas\core\indexing.py", line 1327, in _get_listlike_indexer
    keyarr, indexer = ax._get_indexer_strict(key, axis_name)
  File "C:\Users\xbacos\AppData\Roaming\Python\Python39\site-packages\pandas\core\indexes\base.py", line 5782, in _get_indexer_strict
    self._raise_if_missing(keyarr, indexer, axis_name)
  File "C:\Users\xbacos\AppData\Roaming\Python\Python39\site-packages\pandas\core\indexes\base.py", line 5842, in _raise_if_missing
    raise KeyError(f"None of [{key}] are in the [{axis_name}]")
KeyError: "None of [Int64Index([-2147483648, -2147483648, -2147483648, -2147483648, -2147483648,\n            -2147483648, -2147483648, -2147483648, -2147483648, -2147483648,\n            -2147483648, -2147483648, -2147483648, -2147483648, -2147483648,\n            -2147483648, -2147483648, -2147483648, -2147483648, -2147483648,\n            -2147483648, -2147483648, -2147483648, -2147483648, -2147483648,\n            -2147483648, -2147483648, -2147483648, -2147483648, -2147483648],\n           dtype='int64', name='Code')] are in the [index]"
2023-06-19 15:58:11,500 - SuPy - INFO - All cache cleared.
2023-06-19 15:58:50,160 - SuPy - INFO - All cache cleared.
2023-06-19 15:58:50,364 - SuPy - ERROR - Entries missing from SUEWS_BiogenCO2.txt
Traceback (most recent call last):
  File "C:\OSGeo4W\apps\Python39\lib\site-packages\supy\_load.py", line 887, in build_code_df
    df_code = df_code0.loc[list_code, list_keys]
  File "C:\Users\xbacos\AppData\Roaming\Python\Python39\site-packages\pandas\core\indexing.py", line 961, in __getitem__
    return self._getitem_tuple(key)
  File "C:\Users\xbacos\AppData\Roaming\Python\Python39\site-packages\pandas\core\indexing.py", line 1140, in _getitem_tuple
    return self._getitem_lowerdim(tup)
  File "C:\Users\xbacos\AppData\Roaming\Python\Python39\site-packages\pandas\core\indexing.py", line 843, in _getitem_lowerdim
    return self._getitem_nested_tuple(tup)
  File "C:\Users\xbacos\AppData\Roaming\Python\Python39\site-packages\pandas\core\indexing.py", line 942, in _getitem_nested_tuple
    obj = getattr(obj, self.name)._getitem_axis(key, axis=axis)
  File "C:\Users\xbacos\AppData\Roaming\Python\Python39\site-packages\pandas\core\indexing.py", line 1191, in _getitem_axis
    return self._getitem_iterable(key, axis=axis)
  File "C:\Users\xbacos\AppData\Roaming\Python\Python39\site-packages\pandas\core\indexing.py", line 1132, in _getitem_iterable
    keyarr, indexer = self._get_listlike_indexer(key, axis)
  File "C:\Users\xbacos\AppData\Roaming\Python\Python39\site-packages\pandas\core\indexing.py", line 1327, in _get_listlike_indexer
    keyarr, indexer = ax._get_indexer_strict(key, axis_name)
  File "C:\Users\xbacos\AppData\Roaming\Python\Python39\site-packages\pandas\core\indexes\base.py", line 5782, in _get_indexer_strict
    self._raise_if_missing(keyarr, indexer, axis_name)
  File "C:\Users\xbacos\AppData\Roaming\Python\Python39\site-packages\pandas\core\indexes\base.py", line 5842, in _raise_if_missing
    raise KeyError(f"None of [{key}] are in the [{axis_name}]")
KeyError: "None of [Int64Index([999, 999, 999, 999, 999, 999, 999, 999, 999, 999, 999, 999, 999,\n            999, 999, 999, 999, 999, 999, 999, 999, 999, 999, 999, 999, 999,\n            999, 999, 999, 999],\n           dtype='int64', name='Code')] are in the [index]"
2023-06-19 15:58:50,366 - SuPy - ERROR - missing code:
 [999, 999, 999, 999, 999, 999, 999, 999, 999, 999, 999, 999, 999, 999, 999, 999, 999, 999, 999, 999, 999, 999, 999, 999, 999, 999, 999, 999, 999, 999]
Traceback (most recent call last):
  File "C:\OSGeo4W\apps\Python39\lib\site-packages\supy\_load.py", line 887, in build_code_df
    df_code = df_code0.loc[list_code, list_keys]
  File "C:\Users\xbacos\AppData\Roaming\Python\Python39\site-packages\pandas\core\indexing.py", line 961, in __getitem__
    return self._getitem_tuple(key)
  File "C:\Users\xbacos\AppData\Roaming\Python\Python39\site-packages\pandas\core\indexing.py", line 1140, in _getitem_tuple
    return self._getitem_lowerdim(tup)
  File "C:\Users\xbacos\AppData\Roaming\Python\Python39\site-packages\pandas\core\indexing.py", line 843, in _getitem_lowerdim
    return self._getitem_nested_tuple(tup)
  File "C:\Users\xbacos\AppData\Roaming\Python\Python39\site-packages\pandas\core\indexing.py", line 942, in _getitem_nested_tuple
    obj = getattr(obj, self.name)._getitem_axis(key, axis=axis)
  File "C:\Users\xbacos\AppData\Roaming\Python\Python39\site-packages\pandas\core\indexing.py", line 1191, in _getitem_axis
    return self._getitem_iterable(key, axis=axis)
  File "C:\Users\xbacos\AppData\Roaming\Python\Python39\site-packages\pandas\core\indexing.py", line 1132, in _getitem_iterable
    keyarr, indexer = self._get_listlike_indexer(key, axis)
  File "C:\Users\xbacos\AppData\Roaming\Python\Python39\site-packages\pandas\core\indexing.py", line 1327, in _get_listlike_indexer
    keyarr, indexer = ax._get_indexer_strict(key, axis_name)
  File "C:\Users\xbacos\AppData\Roaming\Python\Python39\site-packages\pandas\core\indexes\base.py", line 5782, in _get_indexer_strict
    self._raise_if_missing(keyarr, indexer, axis_name)
  File "C:\Users\xbacos\AppData\Roaming\Python\Python39\site-packages\pandas\core\indexes\base.py", line 5842, in _raise_if_missing
    raise KeyError(f"None of [{key}] are in the [{axis_name}]")
KeyError: "None of [Int64Index([999, 999, 999, 999, 999, 999, 999, 999, 999, 999, 999, 999, 999,\n            999, 999, 999, 999, 999, 999, 999, 999, 999, 999, 999, 999, 999,\n            999, 999, 999, 999],\n           dtype='int64', name='Code')] are in the [index]"
2023-06-19 15:58:50,368 - SuPy - ERROR - `df_code0` has been dumped into C:\GitHub\suews_prepare_database\df_code0.pkl for debugging!
Traceback (most recent call last):
  File "C:\OSGeo4W\apps\Python39\lib\site-packages\supy\_load.py", line 887, in build_code_df
    df_code = df_code0.loc[list_code, list_keys]
  File "C:\Users\xbacos\AppData\Roaming\Python\Python39\site-packages\pandas\core\indexing.py", line 961, in __getitem__
    return self._getitem_tuple(key)
  File "C:\Users\xbacos\AppData\Roaming\Python\Python39\site-packages\pandas\core\indexing.py", line 1140, in _getitem_tuple
    return self._getitem_lowerdim(tup)
  File "C:\Users\xbacos\AppData\Roaming\Python\Python39\site-packages\pandas\core\indexing.py", line 843, in _getitem_lowerdim
    return self._getitem_nested_tuple(tup)
  File "C:\Users\xbacos\AppData\Roaming\Python\Python39\site-packages\pandas\core\indexing.py", line 942, in _getitem_nested_tuple
    obj = getattr(obj, self.name)._getitem_axis(key, axis=axis)
  File "C:\Users\xbacos\AppData\Roaming\Python\Python39\site-packages\pandas\core\indexing.py", line 1191, in _getitem_axis
    return self._getitem_iterable(key, axis=axis)
  File "C:\Users\xbacos\AppData\Roaming\Python\Python39\site-packages\pandas\core\indexing.py", line 1132, in _getitem_iterable
    keyarr, indexer = self._get_listlike_indexer(key, axis)
  File "C:\Users\xbacos\AppData\Roaming\Python\Python39\site-packages\pandas\core\indexing.py", line 1327, in _get_listlike_indexer
    keyarr, indexer = ax._get_indexer_strict(key, axis_name)
  File "C:\Users\xbacos\AppData\Roaming\Python\Python39\site-packages\pandas\core\indexes\base.py", line 5782, in _get_indexer_strict
    self._raise_if_missing(keyarr, indexer, axis_name)
  File "C:\Users\xbacos\AppData\Roaming\Python\Python39\site-packages\pandas\core\indexes\base.py", line 5842, in _raise_if_missing
    raise KeyError(f"None of [{key}] are in the [{axis_name}]")
KeyError: "None of [Int64Index([999, 999, 999, 999, 999, 999, 999, 999, 999, 999, 999, 999, 999,\n            999, 999, 999, 999, 999, 999, 999, 999, 999, 999, 999, 999, 999,\n            999, 999, 999, 999],\n           dtype='int64', name='Code')] are in the [index]"
2023-06-19 15:58:58,137 - SuPy - INFO - All cache cleared.
2023-06-19 16:09:41,891 - SuPy - INFO - All cache cleared.
2023-06-19 16:10:45,944 - SuPy - INFO - All cache cleared.
2023-06-20 09:05:14,149 - SuPy - INFO - All cache cleared.
2023-06-21 10:37:13,897 - SuPy - INFO - All cache cleared.
2023-06-21 10:37:13,975 - SuPy - ERROR - error [Errno 2] No such file or directory: 'C:\\Users\\xbacos\\OneDrive - University of Gothenburg\\Artikel_4\\temp\\input\\oskar\\SUEWS_WithinGridWaterDist.txt' in reading C:\Users\xbacos\OneDrive - University of Gothenburg\Artikel_4\temp\input\oskar\SUEWS_WithinGridWaterDist.txt!
Traceback (most recent call last):
  File "C:\OSGeo4W\apps\Python39\lib\site-packages\supy\_load.py", line 271, in load_SUEWS_table
    rawdata = pd.read_csv(
  File "C:\Users\xbacos\AppData\Roaming\Python\Python39\site-packages\pandas\util\_decorators.py", line 311, in wrapper
    return func(*args, **kwargs)
  File "C:\Users\xbacos\AppData\Roaming\Python\Python39\site-packages\pandas\io\parsers\readers.py", line 680, in read_csv
    return _read(filepath_or_buffer, kwds)
  File "C:\Users\xbacos\AppData\Roaming\Python\Python39\site-packages\pandas\io\parsers\readers.py", line 575, in _read
    parser = TextFileReader(filepath_or_buffer, **kwds)
  File "C:\Users\xbacos\AppData\Roaming\Python\Python39\site-packages\pandas\io\parsers\readers.py", line 934, in __init__
    self._engine = self._make_engine(f, self.engine)
  File "C:\Users\xbacos\AppData\Roaming\Python\Python39\site-packages\pandas\io\parsers\readers.py", line 1218, in _make_engine
    self.handles = get_handle(  # type: ignore[call-overload]
  File "C:\Users\xbacos\AppData\Roaming\Python\Python39\site-packages\pandas\io\common.py", line 786, in get_handle
    handle = open(
FileNotFoundError: [Errno 2] No such file or directory: 'C:\\Users\\xbacos\\OneDrive - University of Gothenburg\\Artikel_4\\temp\\input\\oskar\\SUEWS_WithinGridWaterDist.txt'
2023-06-21 10:37:48,381 - SuPy - INFO - All cache cleared.
2023-06-21 10:38:27,721 - SuPy - INFO - All cache cleared.
2023-06-21 10:39:30,294 - SuPy - INFO - All cache cleared.
2023-06-21 10:39:48,595 - SuPy - INFO - All cache cleared.
2023-06-21 10:41:25,624 - SuPy - INFO - All cache cleared.
2023-06-21 10:41:36,565 - SuPy - INFO - All cache cleared.
2023-06-21 10:41:37,778 - SuPy - INFO - All cache cleared.
2023-06-21 10:42:10,633 - SuPy - INFO - All cache cleared.
2023-06-21 10:42:12,565 - SuPy - INFO - All cache cleared.
2023-06-21 10:43:21,574 - SuPy - INFO - All cache cleared.
2023-06-21 10:43:22,751 - SuPy - INFO - All cache cleared.
2023-06-21 10:43:56,059 - SuPy - INFO - ====================
2023-06-21 10:43:56,060 - SuPy - INFO - Simulation period:
2023-06-21 10:43:56,061 - SuPy - INFO -   Start: 2017-12-31 23:05:00
2023-06-21 10:43:56,062 - SuPy - INFO -   End: 2018-12-31 23:00:00
2023-06-21 10:43:56,063 - SuPy - INFO - 
2023-06-21 10:43:56,065 - SuPy - INFO - No. of grids: 30
2023-06-21 10:43:56,066 - SuPy - INFO - SuPy is running in serial mode
2023-06-21 11:22:32,808 - SuPy - INFO - ====================
2023-06-21 11:22:32,813 - SuPy - INFO - Simulation period:
2023-06-21 11:22:32,823 - SuPy - INFO -   Start: 2017-12-31 23:05:00
2023-06-21 11:22:32,826 - SuPy - INFO -   End: 2018-12-31 23:00:00
2023-06-21 11:22:32,828 - SuPy - INFO - 
2023-06-21 11:22:45,149 - SuPy - INFO - ====================
2023-06-21 11:22:45,151 - SuPy - INFO - Simulation period:
2023-06-21 11:22:45,152 - SuPy - INFO -   Start: 2017-12-31 23:05:00
2023-06-21 11:22:45,154 - SuPy - INFO -   End: 2018-12-31 23:00:00
2023-06-21 11:22:45,156 - SuPy - INFO - 
2023-06-21 11:23:03,898 - SuPy - INFO - ====================
2023-06-21 11:23:03,899 - SuPy - INFO - Simulation period:
2023-06-21 11:23:03,900 - SuPy - INFO -   Start: 2017-12-31 23:05:00
2023-06-21 11:23:03,902 - SuPy - INFO -   End: 2018-12-31 23:00:00
2023-06-21 11:23:03,903 - SuPy - INFO - 
2023-06-21 11:23:03,904 - SuPy - INFO - No. of grids: 1
2023-06-21 11:23:03,906 - SuPy - INFO - SuPy is running in serial mode
2023-06-21 11:24:22,565 - SuPy - INFO - Execution time: 78.7 s
2023-06-21 11:24:22,567 - SuPy - INFO - ====================

2023-06-21 12:35:33,484 - SuPy - INFO - All cache cleared.
2023-06-21 12:35:34,811 - SuPy - INFO - All cache cleared.
2023-06-21 13:12:23,440 - SuPy - INFO - All cache cleared.
2023-06-21 13:12:23,597 - SuPy - ERROR - Entries missing from SUEWS_NonVeg.txt
Traceback (most recent call last):
  File "C:\OSGeo4W\apps\Python39\lib\site-packages\supy\_load.py", line 887, in build_code_df
    df_code = df_code0.loc[list_code, list_keys]
  File "C:\Users\xbacos\AppData\Roaming\Python\Python39\site-packages\pandas\core\indexing.py", line 961, in __getitem__
    return self._getitem_tuple(key)
  File "C:\Users\xbacos\AppData\Roaming\Python\Python39\site-packages\pandas\core\indexing.py", line 1140, in _getitem_tuple
    return self._getitem_lowerdim(tup)
  File "C:\Users\xbacos\AppData\Roaming\Python\Python39\site-packages\pandas\core\indexing.py", line 843, in _getitem_lowerdim
    return self._getitem_nested_tuple(tup)
  File "C:\Users\xbacos\AppData\Roaming\Python\Python39\site-packages\pandas\core\indexing.py", line 942, in _getitem_nested_tuple
    obj = getattr(obj, self.name)._getitem_axis(key, axis=axis)
  File "C:\Users\xbacos\AppData\Roaming\Python\Python39\site-packages\pandas\core\indexing.py", line 1191, in _getitem_axis
    return self._getitem_iterable(key, axis=axis)
  File "C:\Users\xbacos\AppData\Roaming\Python\Python39\site-packages\pandas\core\indexing.py", line 1132, in _getitem_iterable
    keyarr, indexer = self._get_listlike_indexer(key, axis)
  File "C:\Users\xbacos\AppData\Roaming\Python\Python39\site-packages\pandas\core\indexing.py", line 1327, in _get_listlike_indexer
    keyarr, indexer = ax._get_indexer_strict(key, axis_name)
  File "C:\Users\xbacos\AppData\Roaming\Python\Python39\site-packages\pandas\core\indexes\base.py", line 5782, in _get_indexer_strict
    self._raise_if_missing(keyarr, indexer, axis_name)
  File "C:\Users\xbacos\AppData\Roaming\Python\Python39\site-packages\pandas\core\indexes\base.py", line 5845, in _raise_if_missing
    raise KeyError(f"{not_found} not in index")
KeyError: '[207] not in index'
2023-06-21 13:12:23,601 - SuPy - ERROR - missing code:
 [207, 207]
Traceback (most recent call last):
  File "C:\OSGeo4W\apps\Python39\lib\site-packages\supy\_load.py", line 887, in build_code_df
    df_code = df_code0.loc[list_code, list_keys]
  File "C:\Users\xbacos\AppData\Roaming\Python\Python39\site-packages\pandas\core\indexing.py", line 961, in __getitem__
    return self._getitem_tuple(key)
  File "C:\Users\xbacos\AppData\Roaming\Python\Python39\site-packages\pandas\core\indexing.py", line 1140, in _getitem_tuple
    return self._getitem_lowerdim(tup)
  File "C:\Users\xbacos\AppData\Roaming\Python\Python39\site-packages\pandas\core\indexing.py", line 843, in _getitem_lowerdim
    return self._getitem_nested_tuple(tup)
  File "C:\Users\xbacos\AppData\Roaming\Python\Python39\site-packages\pandas\core\indexing.py", line 942, in _getitem_nested_tuple
    obj = getattr(obj, self.name)._getitem_axis(key, axis=axis)
  File "C:\Users\xbacos\AppData\Roaming\Python\Python39\site-packages\pandas\core\indexing.py", line 1191, in _getitem_axis
    return self._getitem_iterable(key, axis=axis)
  File "C:\Users\xbacos\AppData\Roaming\Python\Python39\site-packages\pandas\core\indexing.py", line 1132, in _getitem_iterable
    keyarr, indexer = self._get_listlike_indexer(key, axis)
  File "C:\Users\xbacos\AppData\Roaming\Python\Python39\site-packages\pandas\core\indexing.py", line 1327, in _get_listlike_indexer
    keyarr, indexer = ax._get_indexer_strict(key, axis_name)
  File "C:\Users\xbacos\AppData\Roaming\Python\Python39\site-packages\pandas\core\indexes\base.py", line 5782, in _get_indexer_strict
    self._raise_if_missing(keyarr, indexer, axis_name)
  File "C:\Users\xbacos\AppData\Roaming\Python\Python39\site-packages\pandas\core\indexes\base.py", line 5845, in _raise_if_missing
    raise KeyError(f"{not_found} not in index")
KeyError: '[207] not in index'
2023-06-21 13:12:23,606 - SuPy - ERROR - `df_code0` has been dumped into C:\GitHub\suews_prepare_database\df_code0.pkl for debugging!
Traceback (most recent call last):
  File "C:\OSGeo4W\apps\Python39\lib\site-packages\supy\_load.py", line 887, in build_code_df
    df_code = df_code0.loc[list_code, list_keys]
  File "C:\Users\xbacos\AppData\Roaming\Python\Python39\site-packages\pandas\core\indexing.py", line 961, in __getitem__
    return self._getitem_tuple(key)
  File "C:\Users\xbacos\AppData\Roaming\Python\Python39\site-packages\pandas\core\indexing.py", line 1140, in _getitem_tuple
    return self._getitem_lowerdim(tup)
  File "C:\Users\xbacos\AppData\Roaming\Python\Python39\site-packages\pandas\core\indexing.py", line 843, in _getitem_lowerdim
    return self._getitem_nested_tuple(tup)
  File "C:\Users\xbacos\AppData\Roaming\Python\Python39\site-packages\pandas\core\indexing.py", line 942, in _getitem_nested_tuple
    obj = getattr(obj, self.name)._getitem_axis(key, axis=axis)
  File "C:\Users\xbacos\AppData\Roaming\Python\Python39\site-packages\pandas\core\indexing.py", line 1191, in _getitem_axis
    return self._getitem_iterable(key, axis=axis)
  File "C:\Users\xbacos\AppData\Roaming\Python\Python39\site-packages\pandas\core\indexing.py", line 1132, in _getitem_iterable
    keyarr, indexer = self._get_listlike_indexer(key, axis)
  File "C:\Users\xbacos\AppData\Roaming\Python\Python39\site-packages\pandas\core\indexing.py", line 1327, in _get_listlike_indexer
    keyarr, indexer = ax._get_indexer_strict(key, axis_name)
  File "C:\Users\xbacos\AppData\Roaming\Python\Python39\site-packages\pandas\core\indexes\base.py", line 5782, in _get_indexer_strict
    self._raise_if_missing(keyarr, indexer, axis_name)
  File "C:\Users\xbacos\AppData\Roaming\Python\Python39\site-packages\pandas\core\indexes\base.py", line 5845, in _raise_if_missing
    raise KeyError(f"{not_found} not in index")
KeyError: '[207] not in index'
2023-06-21 13:12:29,378 - SuPy - INFO - All cache cleared.
2023-06-21 13:12:29,498 - SuPy - ERROR - Entries missing from SUEWS_NonVeg.txt
Traceback (most recent call last):
  File "C:\OSGeo4W\apps\Python39\lib\site-packages\supy\_load.py", line 887, in build_code_df
    df_code = df_code0.loc[list_code, list_keys]
  File "C:\Users\xbacos\AppData\Roaming\Python\Python39\site-packages\pandas\core\indexing.py", line 961, in __getitem__
    return self._getitem_tuple(key)
  File "C:\Users\xbacos\AppData\Roaming\Python\Python39\site-packages\pandas\core\indexing.py", line 1140, in _getitem_tuple
    return self._getitem_lowerdim(tup)
  File "C:\Users\xbacos\AppData\Roaming\Python\Python39\site-packages\pandas\core\indexing.py", line 843, in _getitem_lowerdim
    return self._getitem_nested_tuple(tup)
  File "C:\Users\xbacos\AppData\Roaming\Python\Python39\site-packages\pandas\core\indexing.py", line 942, in _getitem_nested_tuple
    obj = getattr(obj, self.name)._getitem_axis(key, axis=axis)
  File "C:\Users\xbacos\AppData\Roaming\Python\Python39\site-packages\pandas\core\indexing.py", line 1191, in _getitem_axis
    return self._getitem_iterable(key, axis=axis)
  File "C:\Users\xbacos\AppData\Roaming\Python\Python39\site-packages\pandas\core\indexing.py", line 1132, in _getitem_iterable
    keyarr, indexer = self._get_listlike_indexer(key, axis)
  File "C:\Users\xbacos\AppData\Roaming\Python\Python39\site-packages\pandas\core\indexing.py", line 1327, in _get_listlike_indexer
    keyarr, indexer = ax._get_indexer_strict(key, axis_name)
  File "C:\Users\xbacos\AppData\Roaming\Python\Python39\site-packages\pandas\core\indexes\base.py", line 5782, in _get_indexer_strict
    self._raise_if_missing(keyarr, indexer, axis_name)
  File "C:\Users\xbacos\AppData\Roaming\Python\Python39\site-packages\pandas\core\indexes\base.py", line 5845, in _raise_if_missing
    raise KeyError(f"{not_found} not in index")
KeyError: '[207] not in index'
2023-06-21 13:12:29,501 - SuPy - ERROR - missing code:
 [207, 207]
Traceback (most recent call last):
  File "C:\OSGeo4W\apps\Python39\lib\site-packages\supy\_load.py", line 887, in build_code_df
    df_code = df_code0.loc[list_code, list_keys]
  File "C:\Users\xbacos\AppData\Roaming\Python\Python39\site-packages\pandas\core\indexing.py", line 961, in __getitem__
    return self._getitem_tuple(key)
  File "C:\Users\xbacos\AppData\Roaming\Python\Python39\site-packages\pandas\core\indexing.py", line 1140, in _getitem_tuple
    return self._getitem_lowerdim(tup)
  File "C:\Users\xbacos\AppData\Roaming\Python\Python39\site-packages\pandas\core\indexing.py", line 843, in _getitem_lowerdim
    return self._getitem_nested_tuple(tup)
  File "C:\Users\xbacos\AppData\Roaming\Python\Python39\site-packages\pandas\core\indexing.py", line 942, in _getitem_nested_tuple
    obj = getattr(obj, self.name)._getitem_axis(key, axis=axis)
  File "C:\Users\xbacos\AppData\Roaming\Python\Python39\site-packages\pandas\core\indexing.py", line 1191, in _getitem_axis
    return self._getitem_iterable(key, axis=axis)
  File "C:\Users\xbacos\AppData\Roaming\Python\Python39\site-packages\pandas\core\indexing.py", line 1132, in _getitem_iterable
    keyarr, indexer = self._get_listlike_indexer(key, axis)
  File "C:\Users\xbacos\AppData\Roaming\Python\Python39\site-packages\pandas\core\indexing.py", line 1327, in _get_listlike_indexer
    keyarr, indexer = ax._get_indexer_strict(key, axis_name)
  File "C:\Users\xbacos\AppData\Roaming\Python\Python39\site-packages\pandas\core\indexes\base.py", line 5782, in _get_indexer_strict
    self._raise_if_missing(keyarr, indexer, axis_name)
  File "C:\Users\xbacos\AppData\Roaming\Python\Python39\site-packages\pandas\core\indexes\base.py", line 5845, in _raise_if_missing
    raise KeyError(f"{not_found} not in index")
KeyError: '[207] not in index'
2023-06-21 13:12:29,504 - SuPy - ERROR - `df_code0` has been dumped into C:\GitHub\suews_prepare_database\df_code0.pkl for debugging!
Traceback (most recent call last):
  File "C:\OSGeo4W\apps\Python39\lib\site-packages\supy\_load.py", line 887, in build_code_df
    df_code = df_code0.loc[list_code, list_keys]
  File "C:\Users\xbacos\AppData\Roaming\Python\Python39\site-packages\pandas\core\indexing.py", line 961, in __getitem__
    return self._getitem_tuple(key)
  File "C:\Users\xbacos\AppData\Roaming\Python\Python39\site-packages\pandas\core\indexing.py", line 1140, in _getitem_tuple
    return self._getitem_lowerdim(tup)
  File "C:\Users\xbacos\AppData\Roaming\Python\Python39\site-packages\pandas\core\indexing.py", line 843, in _getitem_lowerdim
    return self._getitem_nested_tuple(tup)
  File "C:\Users\xbacos\AppData\Roaming\Python\Python39\site-packages\pandas\core\indexing.py", line 942, in _getitem_nested_tuple
    obj = getattr(obj, self.name)._getitem_axis(key, axis=axis)
  File "C:\Users\xbacos\AppData\Roaming\Python\Python39\site-packages\pandas\core\indexing.py", line 1191, in _getitem_axis
    return self._getitem_iterable(key, axis=axis)
  File "C:\Users\xbacos\AppData\Roaming\Python\Python39\site-packages\pandas\core\indexing.py", line 1132, in _getitem_iterable
    keyarr, indexer = self._get_listlike_indexer(key, axis)
  File "C:\Users\xbacos\AppData\Roaming\Python\Python39\site-packages\pandas\core\indexing.py", line 1327, in _get_listlike_indexer
    keyarr, indexer = ax._get_indexer_strict(key, axis_name)
  File "C:\Users\xbacos\AppData\Roaming\Python\Python39\site-packages\pandas\core\indexes\base.py", line 5782, in _get_indexer_strict
    self._raise_if_missing(keyarr, indexer, axis_name)
  File "C:\Users\xbacos\AppData\Roaming\Python\Python39\site-packages\pandas\core\indexes\base.py", line 5845, in _raise_if_missing
    raise KeyError(f"{not_found} not in index")
KeyError: '[207] not in index'
2023-06-21 13:15:54,035 - SuPy - INFO - All cache cleared.
2023-06-21 13:15:54,112 - SuPy - ERROR - Entries missing from SUEWS_NonVeg.txt
Traceback (most recent call last):
  File "C:\OSGeo4W\apps\Python39\lib\site-packages\supy\_load.py", line 887, in build_code_df
    df_code = df_code0.loc[list_code, list_keys]
  File "C:\Users\xbacos\AppData\Roaming\Python\Python39\site-packages\pandas\core\indexing.py", line 961, in __getitem__
    return self._getitem_tuple(key)
  File "C:\Users\xbacos\AppData\Roaming\Python\Python39\site-packages\pandas\core\indexing.py", line 1140, in _getitem_tuple
    return self._getitem_lowerdim(tup)
  File "C:\Users\xbacos\AppData\Roaming\Python\Python39\site-packages\pandas\core\indexing.py", line 843, in _getitem_lowerdim
    return self._getitem_nested_tuple(tup)
  File "C:\Users\xbacos\AppData\Roaming\Python\Python39\site-packages\pandas\core\indexing.py", line 942, in _getitem_nested_tuple
    obj = getattr(obj, self.name)._getitem_axis(key, axis=axis)
  File "C:\Users\xbacos\AppData\Roaming\Python\Python39\site-packages\pandas\core\indexing.py", line 1191, in _getitem_axis
    return self._getitem_iterable(key, axis=axis)
  File "C:\Users\xbacos\AppData\Roaming\Python\Python39\site-packages\pandas\core\indexing.py", line 1132, in _getitem_iterable
    keyarr, indexer = self._get_listlike_indexer(key, axis)
  File "C:\Users\xbacos\AppData\Roaming\Python\Python39\site-packages\pandas\core\indexing.py", line 1327, in _get_listlike_indexer
    keyarr, indexer = ax._get_indexer_strict(key, axis_name)
  File "C:\Users\xbacos\AppData\Roaming\Python\Python39\site-packages\pandas\core\indexes\base.py", line 5782, in _get_indexer_strict
    self._raise_if_missing(keyarr, indexer, axis_name)
  File "C:\Users\xbacos\AppData\Roaming\Python\Python39\site-packages\pandas\core\indexes\base.py", line 5845, in _raise_if_missing
    raise KeyError(f"{not_found} not in index")
KeyError: '[206] not in index'
2023-06-21 13:15:54,114 - SuPy - ERROR - missing code:
 [206, 206]
Traceback (most recent call last):
  File "C:\OSGeo4W\apps\Python39\lib\site-packages\supy\_load.py", line 887, in build_code_df
    df_code = df_code0.loc[list_code, list_keys]
  File "C:\Users\xbacos\AppData\Roaming\Python\Python39\site-packages\pandas\core\indexing.py", line 961, in __getitem__
    return self._getitem_tuple(key)
  File "C:\Users\xbacos\AppData\Roaming\Python\Python39\site-packages\pandas\core\indexing.py", line 1140, in _getitem_tuple
    return self._getitem_lowerdim(tup)
  File "C:\Users\xbacos\AppData\Roaming\Python\Python39\site-packages\pandas\core\indexing.py", line 843, in _getitem_lowerdim
    return self._getitem_nested_tuple(tup)
  File "C:\Users\xbacos\AppData\Roaming\Python\Python39\site-packages\pandas\core\indexing.py", line 942, in _getitem_nested_tuple
    obj = getattr(obj, self.name)._getitem_axis(key, axis=axis)
  File "C:\Users\xbacos\AppData\Roaming\Python\Python39\site-packages\pandas\core\indexing.py", line 1191, in _getitem_axis
    return self._getitem_iterable(key, axis=axis)
  File "C:\Users\xbacos\AppData\Roaming\Python\Python39\site-packages\pandas\core\indexing.py", line 1132, in _getitem_iterable
    keyarr, indexer = self._get_listlike_indexer(key, axis)
  File "C:\Users\xbacos\AppData\Roaming\Python\Python39\site-packages\pandas\core\indexing.py", line 1327, in _get_listlike_indexer
    keyarr, indexer = ax._get_indexer_strict(key, axis_name)
  File "C:\Users\xbacos\AppData\Roaming\Python\Python39\site-packages\pandas\core\indexes\base.py", line 5782, in _get_indexer_strict
    self._raise_if_missing(keyarr, indexer, axis_name)
  File "C:\Users\xbacos\AppData\Roaming\Python\Python39\site-packages\pandas\core\indexes\base.py", line 5845, in _raise_if_missing
    raise KeyError(f"{not_found} not in index")
KeyError: '[206] not in index'
2023-06-21 13:15:54,117 - SuPy - ERROR - `df_code0` has been dumped into C:\GitHub\suews_prepare_database\df_code0.pkl for debugging!
Traceback (most recent call last):
  File "C:\OSGeo4W\apps\Python39\lib\site-packages\supy\_load.py", line 887, in build_code_df
    df_code = df_code0.loc[list_code, list_keys]
  File "C:\Users\xbacos\AppData\Roaming\Python\Python39\site-packages\pandas\core\indexing.py", line 961, in __getitem__
    return self._getitem_tuple(key)
  File "C:\Users\xbacos\AppData\Roaming\Python\Python39\site-packages\pandas\core\indexing.py", line 1140, in _getitem_tuple
    return self._getitem_lowerdim(tup)
  File "C:\Users\xbacos\AppData\Roaming\Python\Python39\site-packages\pandas\core\indexing.py", line 843, in _getitem_lowerdim
    return self._getitem_nested_tuple(tup)
  File "C:\Users\xbacos\AppData\Roaming\Python\Python39\site-packages\pandas\core\indexing.py", line 942, in _getitem_nested_tuple
    obj = getattr(obj, self.name)._getitem_axis(key, axis=axis)
  File "C:\Users\xbacos\AppData\Roaming\Python\Python39\site-packages\pandas\core\indexing.py", line 1191, in _getitem_axis
    return self._getitem_iterable(key, axis=axis)
  File "C:\Users\xbacos\AppData\Roaming\Python\Python39\site-packages\pandas\core\indexing.py", line 1132, in _getitem_iterable
    keyarr, indexer = self._get_listlike_indexer(key, axis)
  File "C:\Users\xbacos\AppData\Roaming\Python\Python39\site-packages\pandas\core\indexing.py", line 1327, in _get_listlike_indexer
    keyarr, indexer = ax._get_indexer_strict(key, axis_name)
  File "C:\Users\xbacos\AppData\Roaming\Python\Python39\site-packages\pandas\core\indexes\base.py", line 5782, in _get_indexer_strict
    self._raise_if_missing(keyarr, indexer, axis_name)
  File "C:\Users\xbacos\AppData\Roaming\Python\Python39\site-packages\pandas\core\indexes\base.py", line 5845, in _raise_if_missing
    raise KeyError(f"{not_found} not in index")
KeyError: '[206] not in index'
2023-06-21 13:24:31,001 - SuPy - INFO - All cache cleared.
2023-06-21 13:24:31,087 - SuPy - ERROR - Entries missing from SUEWS_NonVeg.txt
Traceback (most recent call last):
  File "C:\OSGeo4W\apps\Python39\lib\site-packages\supy\_load.py", line 887, in build_code_df
    df_code = df_code0.loc[list_code, list_keys]
  File "C:\Users\xbacos\AppData\Roaming\Python\Python39\site-packages\pandas\core\indexing.py", line 961, in __getitem__
    return self._getitem_tuple(key)
  File "C:\Users\xbacos\AppData\Roaming\Python\Python39\site-packages\pandas\core\indexing.py", line 1140, in _getitem_tuple
    return self._getitem_lowerdim(tup)
  File "C:\Users\xbacos\AppData\Roaming\Python\Python39\site-packages\pandas\core\indexing.py", line 843, in _getitem_lowerdim
    return self._getitem_nested_tuple(tup)
  File "C:\Users\xbacos\AppData\Roaming\Python\Python39\site-packages\pandas\core\indexing.py", line 942, in _getitem_nested_tuple
    obj = getattr(obj, self.name)._getitem_axis(key, axis=axis)
  File "C:\Users\xbacos\AppData\Roaming\Python\Python39\site-packages\pandas\core\indexing.py", line 1191, in _getitem_axis
    return self._getitem_iterable(key, axis=axis)
  File "C:\Users\xbacos\AppData\Roaming\Python\Python39\site-packages\pandas\core\indexing.py", line 1132, in _getitem_iterable
    keyarr, indexer = self._get_listlike_indexer(key, axis)
  File "C:\Users\xbacos\AppData\Roaming\Python\Python39\site-packages\pandas\core\indexing.py", line 1327, in _get_listlike_indexer
    keyarr, indexer = ax._get_indexer_strict(key, axis_name)
  File "C:\Users\xbacos\AppData\Roaming\Python\Python39\site-packages\pandas\core\indexes\base.py", line 5782, in _get_indexer_strict
    self._raise_if_missing(keyarr, indexer, axis_name)
  File "C:\Users\xbacos\AppData\Roaming\Python\Python39\site-packages\pandas\core\indexes\base.py", line 5845, in _raise_if_missing
    raise KeyError(f"{not_found} not in index")
KeyError: '[205] not in index'
2023-06-21 13:24:31,089 - SuPy - ERROR - missing code:
 [205, 205]
Traceback (most recent call last):
  File "C:\OSGeo4W\apps\Python39\lib\site-packages\supy\_load.py", line 887, in build_code_df
    df_code = df_code0.loc[list_code, list_keys]
  File "C:\Users\xbacos\AppData\Roaming\Python\Python39\site-packages\pandas\core\indexing.py", line 961, in __getitem__
    return self._getitem_tuple(key)
  File "C:\Users\xbacos\AppData\Roaming\Python\Python39\site-packages\pandas\core\indexing.py", line 1140, in _getitem_tuple
    return self._getitem_lowerdim(tup)
  File "C:\Users\xbacos\AppData\Roaming\Python\Python39\site-packages\pandas\core\indexing.py", line 843, in _getitem_lowerdim
    return self._getitem_nested_tuple(tup)
  File "C:\Users\xbacos\AppData\Roaming\Python\Python39\site-packages\pandas\core\indexing.py", line 942, in _getitem_nested_tuple
    obj = getattr(obj, self.name)._getitem_axis(key, axis=axis)
  File "C:\Users\xbacos\AppData\Roaming\Python\Python39\site-packages\pandas\core\indexing.py", line 1191, in _getitem_axis
    return self._getitem_iterable(key, axis=axis)
  File "C:\Users\xbacos\AppData\Roaming\Python\Python39\site-packages\pandas\core\indexing.py", line 1132, in _getitem_iterable
    keyarr, indexer = self._get_listlike_indexer(key, axis)
  File "C:\Users\xbacos\AppData\Roaming\Python\Python39\site-packages\pandas\core\indexing.py", line 1327, in _get_listlike_indexer
    keyarr, indexer = ax._get_indexer_strict(key, axis_name)
  File "C:\Users\xbacos\AppData\Roaming\Python\Python39\site-packages\pandas\core\indexes\base.py", line 5782, in _get_indexer_strict
    self._raise_if_missing(keyarr, indexer, axis_name)
  File "C:\Users\xbacos\AppData\Roaming\Python\Python39\site-packages\pandas\core\indexes\base.py", line 5845, in _raise_if_missing
    raise KeyError(f"{not_found} not in index")
KeyError: '[205] not in index'
2023-06-21 13:24:31,091 - SuPy - ERROR - `df_code0` has been dumped into C:\GitHub\suews_prepare_database\df_code0.pkl for debugging!
Traceback (most recent call last):
  File "C:\OSGeo4W\apps\Python39\lib\site-packages\supy\_load.py", line 887, in build_code_df
    df_code = df_code0.loc[list_code, list_keys]
  File "C:\Users\xbacos\AppData\Roaming\Python\Python39\site-packages\pandas\core\indexing.py", line 961, in __getitem__
    return self._getitem_tuple(key)
  File "C:\Users\xbacos\AppData\Roaming\Python\Python39\site-packages\pandas\core\indexing.py", line 1140, in _getitem_tuple
    return self._getitem_lowerdim(tup)
  File "C:\Users\xbacos\AppData\Roaming\Python\Python39\site-packages\pandas\core\indexing.py", line 843, in _getitem_lowerdim
    return self._getitem_nested_tuple(tup)
  File "C:\Users\xbacos\AppData\Roaming\Python\Python39\site-packages\pandas\core\indexing.py", line 942, in _getitem_nested_tuple
    obj = getattr(obj, self.name)._getitem_axis(key, axis=axis)
  File "C:\Users\xbacos\AppData\Roaming\Python\Python39\site-packages\pandas\core\indexing.py", line 1191, in _getitem_axis
    return self._getitem_iterable(key, axis=axis)
  File "C:\Users\xbacos\AppData\Roaming\Python\Python39\site-packages\pandas\core\indexing.py", line 1132, in _getitem_iterable
    keyarr, indexer = self._get_listlike_indexer(key, axis)
  File "C:\Users\xbacos\AppData\Roaming\Python\Python39\site-packages\pandas\core\indexing.py", line 1327, in _get_listlike_indexer
    keyarr, indexer = ax._get_indexer_strict(key, axis_name)
  File "C:\Users\xbacos\AppData\Roaming\Python\Python39\site-packages\pandas\core\indexes\base.py", line 5782, in _get_indexer_strict
    self._raise_if_missing(keyarr, indexer, axis_name)
  File "C:\Users\xbacos\AppData\Roaming\Python\Python39\site-packages\pandas\core\indexes\base.py", line 5845, in _raise_if_missing
    raise KeyError(f"{not_found} not in index")
KeyError: '[205] not in index'
2023-06-21 13:25:36,718 - SuPy - INFO - All cache cleared.
2023-06-21 13:25:37,957 - SuPy - INFO - All cache cleared.
2023-06-21 14:15:15,975 - SuPy - INFO - All cache cleared.
2023-06-21 14:15:16,240 - SuPy - ERROR - Entries missing from SUEWS_Soil.txt
Traceback (most recent call last):
  File "C:\OSGeo4W\apps\Python39\lib\site-packages\supy\_load.py", line 887, in build_code_df
    df_code = df_code0.loc[list_code, list_keys]
  File "C:\Users\xbacos\AppData\Roaming\Python\Python39\site-packages\pandas\core\indexing.py", line 961, in __getitem__
    return self._getitem_tuple(key)
  File "C:\Users\xbacos\AppData\Roaming\Python\Python39\site-packages\pandas\core\indexing.py", line 1140, in _getitem_tuple
    return self._getitem_lowerdim(tup)
  File "C:\Users\xbacos\AppData\Roaming\Python\Python39\site-packages\pandas\core\indexing.py", line 843, in _getitem_lowerdim
    return self._getitem_nested_tuple(tup)
  File "C:\Users\xbacos\AppData\Roaming\Python\Python39\site-packages\pandas\core\indexing.py", line 942, in _getitem_nested_tuple
    obj = getattr(obj, self.name)._getitem_axis(key, axis=axis)
  File "C:\Users\xbacos\AppData\Roaming\Python\Python39\site-packages\pandas\core\indexing.py", line 1191, in _getitem_axis
    return self._getitem_iterable(key, axis=axis)
  File "C:\Users\xbacos\AppData\Roaming\Python\Python39\site-packages\pandas\core\indexing.py", line 1132, in _getitem_iterable
    keyarr, indexer = self._get_listlike_indexer(key, axis)
  File "C:\Users\xbacos\AppData\Roaming\Python\Python39\site-packages\pandas\core\indexing.py", line 1327, in _get_listlike_indexer
    keyarr, indexer = ax._get_indexer_strict(key, axis_name)
  File "C:\Users\xbacos\AppData\Roaming\Python\Python39\site-packages\pandas\core\indexes\base.py", line 5782, in _get_indexer_strict
    self._raise_if_missing(keyarr, indexer, axis_name)
  File "C:\Users\xbacos\AppData\Roaming\Python\Python39\site-packages\pandas\core\indexes\base.py", line 5845, in _raise_if_missing
    raise KeyError(f"{not_found} not in index")
KeyError: '[50] not in index'
2023-06-21 14:15:16,241 - SuPy - ERROR - missing code:
 [50, 50, 50, 50, 50, 50, 50, 50, 50, 50, 50, 50]
Traceback (most recent call last):
  File "C:\OSGeo4W\apps\Python39\lib\site-packages\supy\_load.py", line 887, in build_code_df
    df_code = df_code0.loc[list_code, list_keys]
  File "C:\Users\xbacos\AppData\Roaming\Python\Python39\site-packages\pandas\core\indexing.py", line 961, in __getitem__
    return self._getitem_tuple(key)
  File "C:\Users\xbacos\AppData\Roaming\Python\Python39\site-packages\pandas\core\indexing.py", line 1140, in _getitem_tuple
    return self._getitem_lowerdim(tup)
  File "C:\Users\xbacos\AppData\Roaming\Python\Python39\site-packages\pandas\core\indexing.py", line 843, in _getitem_lowerdim
    return self._getitem_nested_tuple(tup)
  File "C:\Users\xbacos\AppData\Roaming\Python\Python39\site-packages\pandas\core\indexing.py", line 942, in _getitem_nested_tuple
    obj = getattr(obj, self.name)._getitem_axis(key, axis=axis)
  File "C:\Users\xbacos\AppData\Roaming\Python\Python39\site-packages\pandas\core\indexing.py", line 1191, in _getitem_axis
    return self._getitem_iterable(key, axis=axis)
  File "C:\Users\xbacos\AppData\Roaming\Python\Python39\site-packages\pandas\core\indexing.py", line 1132, in _getitem_iterable
    keyarr, indexer = self._get_listlike_indexer(key, axis)
  File "C:\Users\xbacos\AppData\Roaming\Python\Python39\site-packages\pandas\core\indexing.py", line 1327, in _get_listlike_indexer
    keyarr, indexer = ax._get_indexer_strict(key, axis_name)
  File "C:\Users\xbacos\AppData\Roaming\Python\Python39\site-packages\pandas\core\indexes\base.py", line 5782, in _get_indexer_strict
    self._raise_if_missing(keyarr, indexer, axis_name)
  File "C:\Users\xbacos\AppData\Roaming\Python\Python39\site-packages\pandas\core\indexes\base.py", line 5845, in _raise_if_missing
    raise KeyError(f"{not_found} not in index")
KeyError: '[50] not in index'
2023-06-21 14:15:16,243 - SuPy - ERROR - `df_code0` has been dumped into C:\GitHub\suews_prepare_database\df_code0.pkl for debugging!
Traceback (most recent call last):
  File "C:\OSGeo4W\apps\Python39\lib\site-packages\supy\_load.py", line 887, in build_code_df
    df_code = df_code0.loc[list_code, list_keys]
  File "C:\Users\xbacos\AppData\Roaming\Python\Python39\site-packages\pandas\core\indexing.py", line 961, in __getitem__
    return self._getitem_tuple(key)
  File "C:\Users\xbacos\AppData\Roaming\Python\Python39\site-packages\pandas\core\indexing.py", line 1140, in _getitem_tuple
    return self._getitem_lowerdim(tup)
  File "C:\Users\xbacos\AppData\Roaming\Python\Python39\site-packages\pandas\core\indexing.py", line 843, in _getitem_lowerdim
    return self._getitem_nested_tuple(tup)
  File "C:\Users\xbacos\AppData\Roaming\Python\Python39\site-packages\pandas\core\indexing.py", line 942, in _getitem_nested_tuple
    obj = getattr(obj, self.name)._getitem_axis(key, axis=axis)
  File "C:\Users\xbacos\AppData\Roaming\Python\Python39\site-packages\pandas\core\indexing.py", line 1191, in _getitem_axis
    return self._getitem_iterable(key, axis=axis)
  File "C:\Users\xbacos\AppData\Roaming\Python\Python39\site-packages\pandas\core\indexing.py", line 1132, in _getitem_iterable
    keyarr, indexer = self._get_listlike_indexer(key, axis)
  File "C:\Users\xbacos\AppData\Roaming\Python\Python39\site-packages\pandas\core\indexing.py", line 1327, in _get_listlike_indexer
    keyarr, indexer = ax._get_indexer_strict(key, axis_name)
  File "C:\Users\xbacos\AppData\Roaming\Python\Python39\site-packages\pandas\core\indexes\base.py", line 5782, in _get_indexer_strict
    self._raise_if_missing(keyarr, indexer, axis_name)
  File "C:\Users\xbacos\AppData\Roaming\Python\Python39\site-packages\pandas\core\indexes\base.py", line 5845, in _raise_if_missing
    raise KeyError(f"{not_found} not in index")
KeyError: '[50] not in index'
2023-06-21 14:21:06,981 - SuPy - INFO - All cache cleared.
2023-06-21 14:21:07,942 - SuPy - ERROR - C:\Users\xbacos\OneDrive - University of Gothenburg\Artikel_4\temp\input\oskar\initialconditionsasdf_2018.nml does not exists!
Traceback (most recent call last):
  File "C:\OSGeo4W\apps\Python39\lib\site-packages\supy\_load.py", line 246, in load_SUEWS_nml
    df_nml = pd.DataFrame(parser.read(p_nml))
  File "C:\Users\xbacos\AppData\Roaming\Python\Python39\site-packages\f90nml\parser.py", line 279, in read
    nml_file = open(nml_fname, 'r') if nml_is_path else nml_fname
FileNotFoundError: [Errno 2] No such file or directory: 'C:\\Users\\xbacos\\OneDrive - University of Gothenburg\\Artikel_4\\temp\\input\\oskar\\initialconditionsasdf_2018.nml'
2023-06-21 14:21:08,279 - SuPy - ERROR - C:\Users\xbacos\OneDrive - University of Gothenburg\Artikel_4\temp\input\oskar\GridLayoutasdf.nml does not exists!
Traceback (most recent call last):
  File "C:\OSGeo4W\apps\Python39\lib\site-packages\supy\_load.py", line 246, in load_SUEWS_nml
    df_nml = pd.DataFrame(parser.read(p_nml))
  File "C:\Users\xbacos\AppData\Roaming\Python\Python39\site-packages\f90nml\parser.py", line 279, in read
    nml_file = open(nml_fname, 'r') if nml_is_path else nml_fname
FileNotFoundError: [Errno 2] No such file or directory: 'C:\\Users\\xbacos\\OneDrive - University of Gothenburg\\Artikel_4\\temp\\input\\oskar\\GridLayoutasdf.nml'
2023-06-21 14:21:08,524 - SuPy - INFO - All cache cleared.
2023-06-21 14:21:09,544 - SuPy - ERROR - C:\Users\xbacos\OneDrive - University of Gothenburg\Artikel_4\temp\input\oskar\initialconditionsasdf_2018.nml does not exists!
Traceback (most recent call last):
  File "C:\OSGeo4W\apps\Python39\lib\site-packages\supy\_load.py", line 246, in load_SUEWS_nml
    df_nml = pd.DataFrame(parser.read(p_nml))
  File "C:\Users\xbacos\AppData\Roaming\Python\Python39\site-packages\f90nml\parser.py", line 279, in read
    nml_file = open(nml_fname, 'r') if nml_is_path else nml_fname
FileNotFoundError: [Errno 2] No such file or directory: 'C:\\Users\\xbacos\\OneDrive - University of Gothenburg\\Artikel_4\\temp\\input\\oskar\\initialconditionsasdf_2018.nml'
2023-06-21 14:21:09,892 - SuPy - ERROR - C:\Users\xbacos\OneDrive - University of Gothenburg\Artikel_4\temp\input\oskar\GridLayoutasdf.nml does not exists!
Traceback (most recent call last):
  File "C:\OSGeo4W\apps\Python39\lib\site-packages\supy\_load.py", line 246, in load_SUEWS_nml
    df_nml = pd.DataFrame(parser.read(p_nml))
  File "C:\Users\xbacos\AppData\Roaming\Python\Python39\site-packages\f90nml\parser.py", line 279, in read
    nml_file = open(nml_fname, 'r') if nml_is_path else nml_fname
FileNotFoundError: [Errno 2] No such file or directory: 'C:\\Users\\xbacos\\OneDrive - University of Gothenburg\\Artikel_4\\temp\\input\\oskar\\GridLayoutasdf.nml'
2023-06-21 14:21:32,643 - SuPy - INFO - All cache cleared.
2023-06-21 14:21:33,333 - SuPy - ERROR - C:\Users\xbacos\OneDrive - University of Gothenburg\Artikel_4\temp\input\oskar\initialconditionsasf_2018.nml does not exists!
Traceback (most recent call last):
  File "C:\OSGeo4W\apps\Python39\lib\site-packages\supy\_load.py", line 246, in load_SUEWS_nml
    df_nml = pd.DataFrame(parser.read(p_nml))
  File "C:\Users\xbacos\AppData\Roaming\Python\Python39\site-packages\f90nml\parser.py", line 279, in read
    nml_file = open(nml_fname, 'r') if nml_is_path else nml_fname
FileNotFoundError: [Errno 2] No such file or directory: 'C:\\Users\\xbacos\\OneDrive - University of Gothenburg\\Artikel_4\\temp\\input\\oskar\\initialconditionsasf_2018.nml'
2023-06-21 14:21:33,555 - SuPy - ERROR - C:\Users\xbacos\OneDrive - University of Gothenburg\Artikel_4\temp\input\oskar\GridLayoutasf.nml does not exists!
Traceback (most recent call last):
  File "C:\OSGeo4W\apps\Python39\lib\site-packages\supy\_load.py", line 246, in load_SUEWS_nml
    df_nml = pd.DataFrame(parser.read(p_nml))
  File "C:\Users\xbacos\AppData\Roaming\Python\Python39\site-packages\f90nml\parser.py", line 279, in read
    nml_file = open(nml_fname, 'r') if nml_is_path else nml_fname
FileNotFoundError: [Errno 2] No such file or directory: 'C:\\Users\\xbacos\\OneDrive - University of Gothenburg\\Artikel_4\\temp\\input\\oskar\\GridLayoutasf.nml'
2023-06-21 14:21:33,767 - SuPy - INFO - All cache cleared.
2023-06-21 14:21:34,493 - SuPy - ERROR - C:\Users\xbacos\OneDrive - University of Gothenburg\Artikel_4\temp\input\oskar\initialconditionsasf_2018.nml does not exists!
Traceback (most recent call last):
  File "C:\OSGeo4W\apps\Python39\lib\site-packages\supy\_load.py", line 246, in load_SUEWS_nml
    df_nml = pd.DataFrame(parser.read(p_nml))
  File "C:\Users\xbacos\AppData\Roaming\Python\Python39\site-packages\f90nml\parser.py", line 279, in read
    nml_file = open(nml_fname, 'r') if nml_is_path else nml_fname
FileNotFoundError: [Errno 2] No such file or directory: 'C:\\Users\\xbacos\\OneDrive - University of Gothenburg\\Artikel_4\\temp\\input\\oskar\\initialconditionsasf_2018.nml'
2023-06-21 14:21:34,752 - SuPy - ERROR - C:\Users\xbacos\OneDrive - University of Gothenburg\Artikel_4\temp\input\oskar\GridLayoutasf.nml does not exists!
Traceback (most recent call last):
  File "C:\OSGeo4W\apps\Python39\lib\site-packages\supy\_load.py", line 246, in load_SUEWS_nml
    df_nml = pd.DataFrame(parser.read(p_nml))
  File "C:\Users\xbacos\AppData\Roaming\Python\Python39\site-packages\f90nml\parser.py", line 279, in read
    nml_file = open(nml_fname, 'r') if nml_is_path else nml_fname
FileNotFoundError: [Errno 2] No such file or directory: 'C:\\Users\\xbacos\\OneDrive - University of Gothenburg\\Artikel_4\\temp\\input\\oskar\\GridLayoutasf.nml'
2023-06-21 14:22:20,635 - SuPy - INFO - All cache cleared.
2023-06-21 14:22:23,251 - SuPy - INFO - All cache cleared.
